I'm sorry, but an uncaught exception occurred.

While running game code:
  File "game/script00.rpy", line 501, in script call
    call dungeon
  File "game/script00.rpy", line 581, in script
    $ current_battle = Battle()
  File "game/script00.rpy", line 581, in <module>
    $ current_battle = Battle()
  File "game/dungeonBattle.rpy", line 49, in __init__
    self.loadBattle(battleNumber)
  File "game/dungeonBattle.rpy", line 137, in loadBattle
    if self.number ==16:
AttributeError: 'Battle' object has no attribute 'number'

-- Full Traceback ------------------------------------------------------------

Full traceback:
  File "game/script00.rpy", line 501, in script call
    call dungeon
  File "game/script00.rpy", line 581, in script
    $ current_battle = Battle()
  File "/home/digiholic/workspace/SummonerSweetheart-0.9-all/renpy/ast.py", line 785, in execute
    renpy.python.py_exec_bytecode(self.code.bytecode, self.hide, store=self.store)
  File "/home/digiholic/workspace/SummonerSweetheart-0.9-all/renpy/python.py", line 1382, in py_exec_bytecode
    exec bytecode in globals, locals
  File "game/script00.rpy", line 581, in <module>
    $ current_battle = Battle()
  File "game/dungeonBattle.rpy", line 49, in __init__
    self.loadBattle(battleNumber)
  File "game/dungeonBattle.rpy", line 137, in loadBattle
    if self.number ==16:
AttributeError: 'Battle' object has no attribute 'number'

Linux-3.16.0-41-generic-x86_64-with-debian-jessie-sid
Ren'Py 6.18.3.761
Summoner Sweetheart 0.9
